<?xml version="1.0"?>
<robot xmlns:xacro="http://www.ros.org/wiki/xacro" name="robot_essentials">

  <!-- Wheel link macro -->
  <xacro:macro name="robot_wheel" params="prefix">
    <link name="${prefix}_wheel">
      <visual>
        <origin xyz="0.0 0.0 0.0" rpy="1.5707963267949 0.0 0.0"/>
        <geometry>
          <mesh
            filename="package://robot_description/meshes/wheel.stl"
            scale="1.0 1.0 1.0"/>
        </geometry>
        <material name="">
          <color rgba="0.79216 0.81961 0.93333 1.0"/>
        </material>
      </visual>
      <collision>
        <origin xyz="0.0 0.0 0.0" rpy="1.5707963267949 0.0 0.0"/>
        <geometry>
          <mesh
          filename="package://robot_description/meshes/wheel.stl"
          scale="1.0 1.0 1.0"/>
        </geometry>
      </collision>
      <inertial>
        <origin
          xyz="-4.1867E-18 0.0068085 -1.65658661799998E-18"
          rpy="0.0 0.0 0.0"/>
        <mass value="2.6578"/>
        <inertia
          ixx="0.00856502765719703"
          ixy="1.5074118157338E-19"
          ixz="-4.78150098725052E-19"
          iyy="0.013670640432096"
          iyz="-2.68136447099727E-19"
          izz="0.00856502765719703"/>
      </inertial>
    </link>
  </xacro:macro>

  <!-- Wheel joint macro -->
  <xacro:macro name="wheel_joint" params="prefix origin">
    <joint name="${prefix}_wheel_joint" type="continuous">
      <parent link="base_link"/>
      <child link="${prefix}_wheel"/>
      <axis xyz="0 1 0"/>
      <origin xyz="${origin}" rpy="0 0 0"/>
    </joint>
  </xacro:macro>

</robot>
